Workbook

Sheet Package Table and Charts
A1: Objective Code | B1: Objective Description | C1: Prerequisite Objectives | D1: Prereqs Met? | E1: Estimated TTC (low, hrs) | F1: Estimated TTC (high, hrs) | G1: Completed?
A2: 1.0.0 | B2: Sand -> Si Wafer Process Estabilished | D2: {=PrereqsMet(C2, $A$2:$A$132, $G$2:$G$132, A2)} -> YES
A3: 1.1.0 | B3: Purifying Sand into SiO2 | D3: {=PrereqsMet(C3, $A$2:$A$132, $G$2:$G$132, A3)} -> YES | E3: 50 | F3: 200
A4: 1.2.0 | B4: Purifying SiO2 into 9N SiO2 | C4: 1.1.0 | D4: {=PrereqsMet(C4, $A$2:$A$132, $G$2:$G$132, A4)} -> NO | E4: 100 | F4: 500
A5: 1.3.0 | B5: SiO2 into Polycrystalline Si | C5: 1.2.0 | D5: {=PrereqsMet(C5, $A$2:$A$132, $G$2:$G$132, A5)} -> NO | E5: 100 | F5: 200
A6: 1.4.0 | B6: Polycrystalline Si into Doped Monocrystalline Si | C6: 1.3.0 | D6: {=PrereqsMet(C6, $A$2:$A$132, $G$2:$G$132, A6)} -> NO | E6: 200 | F6: 600
A7: 1.5.0 | B7: Boule Slicing, Wafer Polishing | C7: 1.4.0 | D7: {=PrereqsMet(C7, $A$2:$A$132, $G$2:$G$132, A7)} -> NO | E7: 30 | F7: 200
A8: 2.0.0 | B8: Photolithography and Chip Fabrication Process | D8: {=PrereqsMet(C8, $A$2:$A$132, $G$2:$G$132, A8)} -> YES
A9: 2.1.0 | B9: Dummy masks for simple devices | D9: {=PrereqsMet(C9, $A$2:$A$132, $G$2:$G$132, A9)} -> YES | E9: 1 | F9: 8
A10: 2.2.0 | B10: Photoresist application and development equipment | D10: {=PrereqsMet(C10, $A$2:$A$132, $G$2:$G$132, A10)} -> YES | E10: 3 | F10: 20
A11: 2.3.0 | B11: Confirmed pattern transfer via masks/patterns | C11: 2.2.0, 2.1.0, 7.3.0 | D11: {=PrereqsMet(C11, $A$2:$A$132, $G$2:$G$132, A11)} -> NO | E11: 10 | F11: 100
A12: 2.4.0 | B12: Metal Thin Film Deposition Process confirmed | C12: 1.5.0 | D12: {=PrereqsMet(C12, $A$2:$A$132, $G$2:$G$132, A12)} -> NO | E12: 30 | F12: 200
A13: 2.5.0 | B13: Dry Etching process estabilished | C13: 2.3.0 | D13: {=PrereqsMet(C13, $A$2:$A$132, $G$2:$G$132, A13)} -> NO | E13: 20 | F13: 150
A14: 2.6.0 | B14: Oxide Growth System estabilished | C14: 1.5.0 | D14: {=PrereqsMet(C14, $A$2:$A$132, $G$2:$G$132, A14)} -> NO | E14: 20 | F14: 80
A15: 2.7.0 | B15: Selective Doping process estabilished | C15: 1.5.0, 2.1.0 | D15: {=PrereqsMet(C15, $A$2:$A$132, $G$2:$G$132, A15)} -> NO | E15: 40 | F15: 200
A16: 2.8.0 | B16: Dielectric of choice deposited onto wafer | C16: 1.5.0 | D16: {=PrereqsMet(C16, $A$2:$A$132, $G$2:$G$132, A16)} -> NO | E16: 20 | F16: 300
A17: 3.0.0 | B17: Die Packaging Process Complete | D17: {=PrereqsMet(C17, $A$2:$A$132, $G$2:$G$132, A17)} -> YES | E17: 200 | F17: 2000
A18: 4.0.0 | B18: Characterization Equipment Acquired | C18: 1.5.0 | D18: {=PrereqsMet(C18, $A$2:$A$132, $G$2:$G$132, A18)} -> NO | E18: 0 | F18: 0
A19: 5.0.0 | B19: CPU Architecture Estabilished | D19: {=PrereqsMet(C19, $A$2:$A$132, $G$2:$G$132, A19)} -> YES
A20: 5.1.0 | B20: Bus Width Selected | D20: {=PrereqsMet(C20, $A$2:$A$132, $G$2:$G$132, A20)} -> YES | E20: 0 | F20: 0 | G20: YES
A21: 5.2.0 | B21: Assembly Instruction Architecture | C21: 5.1.0 | D21: {=PrereqsMet(C21, $A$2:$A$132, $G$2:$G$132, A21)} -> YES | E21: 1 | F21: 3 | G21: YES
A22: 5.3.0 | B22: ALU requirements outlined | D22: {=PrereqsMet(C22, $A$2:$A$132, $G$2:$G$132, A22)} -> YES | E22: 1 | F22: 3 | G22: YES
A23: 5.4.0 | B23: Bus Logic requirements outlined | D23: {=PrereqsMet(C23, $A$2:$A$132, $G$2:$G$132, A23)} -> YES | E23: 1 | F23: 2 | G23: YES
A24: 5.5.0 | B24: Port Requirements outlined | D24: {=PrereqsMet(C24, $A$2:$A$132, $G$2:$G$132, A24)} -> YES | E24: 1 | F24: 2
A25: 5.6.0 | B25: Register File requirements outlined | D25: {=PrereqsMet(C25, $A$2:$A$132, $G$2:$G$132, A25)} -> YES | E25: 1 | F25: 2 | G25: YES
A26: 5.7.0 | B26: Control Signals Listed | D26: {=PrereqsMet(C26, $A$2:$A$132, $G$2:$G$132, A26)} -> YES | E26: 1 | F26: 2
A27: 6.0.0 | B27: Logisim Simulation Completed | C27: 5.0.0 | D27: {=PrereqsMet(C27, $A$2:$A$132, $G$2:$G$132, A27)} -> NO
A28: 6.1.0 | B28: Arithmetic Logic Unit | C28: 5.0.0, 5.3.0 | D28: {=PrereqsMet(C28, $A$2:$A$132, $G$2:$G$132, A28)} -> NO | E28: 2 | F28: 3
A29: 6.2.0 | B29: Register File | C29: 5.0.0, 5.6.0 | D29: {=PrereqsMet(C29, $A$2:$A$132, $G$2:$G$132, A29)} -> NO | E29: 1 | F29: 2
A30: 6.3.0 | B30: Bus Logic | C30: 5.0.0, 5.4.0 | D30: {=PrereqsMet(C30, $A$2:$A$132, $G$2:$G$132, A30)} -> NO | E30: 3 | F30: 5
A31: 6.4.0 | B31: Port Handlers | C31: 5.0.0, 5.5.0 | D31: {=PrereqsMet(C31, $A$2:$A$132, $G$2:$G$132, A31)} -> NO | E31: 2 | F31: 3
A32: 6.5.0 | B32: EEPROM written | C32: 5.0.0, 5.7.0 | D32: {=PrereqsMet(C32, $A$2:$A$132, $G$2:$G$132, A32)} -> NO | E32: 2 | F32: 3
A33: 6.6.0 | B33: Full Scale Test | C33: 6.5.0, 6.4.0, 6.3.0, 6.2.0, 6.1.0 | D33: {=PrereqsMet(C33, $A$2:$A$132, $G$2:$G$132, A33)} -> NO | E33: 10 | F33: 20
A34: 7.0.0 | B34: CMOS TTL Schematic | C34: 6.0.0 | D34: {=PrereqsMet(C34, $A$2:$A$132, $G$2:$G$132, A34)} -> NO
A35: 7.1.0 | B35: CMOS Transistor Circuit Schematic | C35: 6.0.0 | D35: {=PrereqsMet(C35, $A$2:$A$132, $G$2:$G$132, A35)} -> NO | E35: 3 | F35: 5
A36: 7.2.0 | B36: CMOS Transistor Count and Critical Path Analysis | C36: 7.1.0 | D36: {=PrereqsMet(C36, $A$2:$A$132, $G$2:$G$132, A36)} -> NO | E36: 2 | F36: 5
A37: 7.3.0 | B37: Photolithography Mask / Pattern Designs | C37: 2.1.0, 7.1.0 | D37: {=PrereqsMet(C37, $A$2:$A$132, $G$2:$G$132, A37)} -> NO | E37: 10 | F37: 30
A38: 8.0.0 | B38: TBASM Assembler | C38: 5.2.0 | D38: {=PrereqsMet(C38, $A$2:$A$132, $G$2:$G$132, A38)} -> YES
A39: 8.1.0 | B39: Basic C-based file IO system | D39: {=PrereqsMet(C39, $A$2:$A$132, $G$2:$G$132, A39)} -> YES | E39: 3 | F39: 5
A40: 8.2.0 | B40: Single-Pass Lexer implemented | C40: 8.1.0 | D40: {=PrereqsMet(C40, $A$2:$A$132, $G$2:$G$132, A40)} -> NO | E40: 2 | F40: 5
...

Sheet Charts Backend
A1: Misc Charts, non Row Dependent
A2: Objectives Remaining | B2: =COUNTA('Package Table and Charts'!A2:A1025) - B3 -> 47
A3: Objectives Finished | B3: =COUNTA('Package Table and Charts'!G2:G1025) -> 5
A5: Objective-hours Finished | B5: =SUMIFS('Package Table and Charts'!E2:E1025, 'Package Table and Charts'!G2:G1025, "<>") -> 4 | C5: =SUMIFS('Package Table and Charts'!F2:F1025, 'Package Table and Charts'!G2:G1025, "<>") -> 10
A6: Objective-hours Remaining | B6: =SUM('Package Table and Charts'!E2:E1025)-B5 -> 953 | C6: =SUM('Package Table and Charts'!F2:F1025)-C5 -> 5163
B7: est. best case | C7: est. worst case
A8: Objective-hours Finished | B8: =C5 -> 10
A9: Objective-hours Remaining | B9: =C6 -> 5163
